2021-09-23 11:43:43,182 INFO    MainThread:4322 [internal.py:wandb_internal():89] W&B internal server running at pid: 4322, started at: 2021-09-23 11:43:43.181581
2021-09-23 11:43:43,188 DEBUG   HandlerThread:4322 [handler.py:handle_request():126] handle_request: run_start
2021-09-23 11:43:43,196 INFO    WriterThread:4322 [datastore.py:open_for_write():77] open: output/wandb/offline-run-20210923_114342-3omd6fx0/run-3omd6fx0.wandb
2021-09-23 11:43:45,238 DEBUG   HandlerThread:4322 [meta.py:__init__():40] meta init
2021-09-23 11:43:45,238 DEBUG   HandlerThread:4322 [meta.py:__init__():54] meta init done
2021-09-23 11:43:45,238 DEBUG   HandlerThread:4322 [meta.py:probe():211] probe
2021-09-23 11:43:45,245 DEBUG   HandlerThread:4322 [meta.py:_setup_git():201] setup git
2021-09-23 11:43:45,281 DEBUG   HandlerThread:4322 [meta.py:_setup_git():208] setup git done
2021-09-23 11:43:45,281 DEBUG   HandlerThread:4322 [meta.py:_save_pip():58] save pip
2021-09-23 11:43:45,282 DEBUG   HandlerThread:4322 [meta.py:_save_pip():72] save pip done
2021-09-23 11:43:45,282 DEBUG   HandlerThread:4322 [meta.py:_save_conda():79] save conda
2021-09-23 11:43:51,595 DEBUG   HandlerThread:4322 [meta.py:_save_conda():87] save conda done
2021-09-23 11:43:51,595 DEBUG   HandlerThread:4322 [meta.py:probe():249] probe done
2021-09-23 11:43:52,715 WARNING MainThread:4322 [internal.py:wandb_internal():145] Internal process interrupt: 1
2021-09-23 11:43:52,888 WARNING MainThread:4322 [internal.py:wandb_internal():145] Internal process interrupt: 2
2021-09-23 11:43:52,888 ERROR   MainThread:4322 [internal.py:wandb_internal():148] Internal process interrupted.
2021-09-23 11:43:53,202 INFO    SenderThread:4322 [sender.py:finish():979] shutting down sender
2021-09-23 11:43:53,599 INFO    WriterThread:4322 [datastore.py:close():281] close: output/wandb/offline-run-20210923_114342-3omd6fx0/run-3omd6fx0.wandb
2021-09-23 11:43:53,601 INFO    HandlerThread:4322 [handler.py:finish():683] shutting down handler
2021-09-23 11:43:53,602 INFO    MainThread:4322 [internal.py:handle_exit():76] Internal process exited
