2021-10-11 15:53:38,811 INFO    MainThread:15429 [internal.py:wandb_internal():91] W&B internal server running at pid: 15429, started at: 2021-10-11 15:53:38.810847
2021-10-11 15:53:38,813 INFO    WriterThread:15429 [datastore.py:open_for_write():80] open: output/wandb/offline-run-20211011_155337-3492y4m5/run-3492y4m5.wandb
2021-10-11 15:53:38,817 DEBUG   HandlerThread:15429 [handler.py:handle_request():124] handle_request: run_start
2021-10-11 15:53:39,719 DEBUG   HandlerThread:15429 [meta.py:__init__():39] meta init
2021-10-11 15:53:39,719 DEBUG   HandlerThread:15429 [meta.py:__init__():53] meta init done
2021-10-11 15:53:39,719 DEBUG   HandlerThread:15429 [meta.py:probe():210] probe
2021-10-11 15:53:39,726 DEBUG   HandlerThread:15429 [meta.py:_setup_git():200] setup git
2021-10-11 15:53:39,749 DEBUG   HandlerThread:15429 [meta.py:_setup_git():207] setup git done
2021-10-11 15:53:39,750 DEBUG   HandlerThread:15429 [meta.py:_save_pip():57] save pip
2021-10-11 15:53:39,751 DEBUG   HandlerThread:15429 [meta.py:_save_pip():71] save pip done
2021-10-11 15:53:39,751 DEBUG   HandlerThread:15429 [meta.py:_save_conda():78] save conda
2021-10-11 15:53:42,500 DEBUG   HandlerThread:15429 [meta.py:_save_conda():86] save conda done
2021-10-11 15:53:42,501 DEBUG   HandlerThread:15429 [meta.py:probe():252] probe done
2021-10-11 15:55:47,695 WARNING MainThread:15429 [internal.py:wandb_internal():147] Internal process interrupt: 1
2021-10-11 15:55:47,891 WARNING MainThread:15429 [internal.py:wandb_internal():147] Internal process interrupt: 2
2021-10-11 15:55:47,891 ERROR   MainThread:15429 [internal.py:wandb_internal():150] Internal process interrupted.
2021-10-11 15:55:48,350 INFO    WriterThread:15429 [datastore.py:close():288] close: output/wandb/offline-run-20211011_155337-3492y4m5/run-3492y4m5.wandb
2021-10-11 15:55:48,358 INFO    HandlerThread:15429 [handler.py:finish():658] shutting down handler
2021-10-11 15:55:48,839 INFO    SenderThread:15429 [sender.py:finish():947] shutting down sender
2021-10-11 15:55:48,840 INFO    MainThread:15429 [internal.py:handle_exit():78] Internal process exited
