2021-10-11 15:22:16,278 INFO    MainThread:13095 [internal.py:wandb_internal():91] W&B internal server running at pid: 13095, started at: 2021-10-11 15:22:16.278524
2021-10-11 15:22:16,283 DEBUG   HandlerThread:13095 [handler.py:handle_request():124] handle_request: run_start
2021-10-11 15:22:16,284 INFO    WriterThread:13095 [datastore.py:open_for_write():80] open: output/wandb/offline-run-20211011_152215-1mxe3i5z/run-1mxe3i5z.wandb
2021-10-11 15:22:17,195 DEBUG   HandlerThread:13095 [meta.py:__init__():39] meta init
2021-10-11 15:22:17,195 DEBUG   HandlerThread:13095 [meta.py:__init__():53] meta init done
2021-10-11 15:22:17,195 DEBUG   HandlerThread:13095 [meta.py:probe():210] probe
2021-10-11 15:22:17,202 DEBUG   HandlerThread:13095 [meta.py:_setup_git():200] setup git
2021-10-11 15:22:17,224 DEBUG   HandlerThread:13095 [meta.py:_setup_git():207] setup git done
2021-10-11 15:22:17,224 DEBUG   HandlerThread:13095 [meta.py:_save_pip():57] save pip
2021-10-11 15:22:17,225 DEBUG   HandlerThread:13095 [meta.py:_save_pip():71] save pip done
2021-10-11 15:22:17,225 DEBUG   HandlerThread:13095 [meta.py:_save_conda():78] save conda
2021-10-11 15:22:20,056 DEBUG   HandlerThread:13095 [meta.py:_save_conda():86] save conda done
2021-10-11 15:22:20,056 DEBUG   HandlerThread:13095 [meta.py:probe():252] probe done
2021-10-11 15:51:01,047 WARNING MainThread:13095 [internal.py:wandb_internal():147] Internal process interrupt: 1
2021-10-11 15:51:01,222 WARNING MainThread:13095 [internal.py:wandb_internal():147] Internal process interrupt: 2
2021-10-11 15:51:01,222 ERROR   MainThread:13095 [internal.py:wandb_internal():150] Internal process interrupted.
2021-10-11 15:51:01,322 INFO    WriterThread:13095 [datastore.py:close():288] close: output/wandb/offline-run-20211011_152215-1mxe3i5z/run-1mxe3i5z.wandb
2021-10-11 15:51:01,341 INFO    HandlerThread:13095 [handler.py:finish():658] shutting down handler
2021-10-11 15:51:01,565 INFO    SenderThread:13095 [sender.py:finish():947] shutting down sender
2021-10-11 15:51:01,566 INFO    MainThread:13095 [internal.py:handle_exit():78] Internal process exited
