2021-10-07 14:42:12,090 INFO    MainThread:32043 [internal.py:wandb_internal():89] W&B internal server running at pid: 32043, started at: 2021-10-07 14:42:12.088601
2021-10-07 14:42:12,097 DEBUG   HandlerThread:32043 [handler.py:handle_request():126] handle_request: run_start
2021-10-07 14:42:12,106 INFO    WriterThread:32043 [datastore.py:open_for_write():77] open: output/wandb/offline-run-20211007_144210-35uww4ua/run-35uww4ua.wandb
2021-10-07 14:42:16,655 DEBUG   HandlerThread:32043 [meta.py:__init__():40] meta init
2021-10-07 14:42:16,656 DEBUG   HandlerThread:32043 [meta.py:__init__():54] meta init done
2021-10-07 14:42:16,656 DEBUG   HandlerThread:32043 [meta.py:probe():211] probe
2021-10-07 14:42:16,676 DEBUG   HandlerThread:32043 [meta.py:_setup_git():201] setup git
2021-10-07 14:42:16,718 DEBUG   HandlerThread:32043 [meta.py:_setup_git():208] setup git done
2021-10-07 14:42:16,718 DEBUG   HandlerThread:32043 [meta.py:_save_pip():58] save pip
2021-10-07 14:42:16,719 DEBUG   HandlerThread:32043 [meta.py:_save_pip():72] save pip done
2021-10-07 14:42:16,719 DEBUG   HandlerThread:32043 [meta.py:_save_conda():79] save conda
2021-10-07 14:42:24,215 DEBUG   HandlerThread:32043 [meta.py:_save_conda():87] save conda done
2021-10-07 14:42:24,216 DEBUG   HandlerThread:32043 [meta.py:probe():249] probe done
2021-10-07 14:42:33,153 WARNING MainThread:32043 [internal.py:wandb_internal():145] Internal process interrupt: 1
2021-10-07 14:42:33,341 WARNING MainThread:32043 [internal.py:wandb_internal():145] Internal process interrupt: 2
2021-10-07 14:42:33,341 ERROR   MainThread:32043 [internal.py:wandb_internal():148] Internal process interrupted.
2021-10-07 14:42:34,223 INFO    SenderThread:32043 [sender.py:finish():979] shutting down sender
2021-10-07 14:42:34,226 INFO    WriterThread:32043 [datastore.py:close():281] close: output/wandb/offline-run-20211007_144210-35uww4ua/run-35uww4ua.wandb
2021-10-07 14:42:34,234 INFO    HandlerThread:32043 [handler.py:finish():683] shutting down handler
2021-10-07 14:42:34,236 INFO    MainThread:32043 [internal.py:handle_exit():76] Internal process exited
