2021-10-13 15:36:38,352 INFO    MainThread:24686 [internal.py:wandb_internal():91] W&B internal server running at pid: 24686, started at: 2021-10-13 15:36:38.352269
2021-10-13 15:36:38,356 INFO    WriterThread:24686 [datastore.py:open_for_write():80] open: output/wandb/offline-run-20211013_153637-19kw7vmp/run-19kw7vmp.wandb
2021-10-13 15:36:38,358 DEBUG   HandlerThread:24686 [handler.py:handle_request():124] handle_request: run_start
2021-10-13 15:36:39,251 DEBUG   HandlerThread:24686 [meta.py:__init__():39] meta init
2021-10-13 15:36:39,251 DEBUG   HandlerThread:24686 [meta.py:__init__():53] meta init done
2021-10-13 15:36:39,251 DEBUG   HandlerThread:24686 [meta.py:probe():210] probe
2021-10-13 15:36:39,258 DEBUG   HandlerThread:24686 [meta.py:_setup_git():200] setup git
2021-10-13 15:36:39,280 DEBUG   HandlerThread:24686 [meta.py:_setup_git():207] setup git done
2021-10-13 15:36:39,281 DEBUG   HandlerThread:24686 [meta.py:_save_pip():57] save pip
2021-10-13 15:36:39,281 DEBUG   HandlerThread:24686 [meta.py:_save_pip():71] save pip done
2021-10-13 15:36:39,281 DEBUG   HandlerThread:24686 [meta.py:_save_conda():78] save conda
2021-10-13 15:36:42,058 DEBUG   HandlerThread:24686 [meta.py:_save_conda():86] save conda done
2021-10-13 15:36:42,058 DEBUG   HandlerThread:24686 [meta.py:probe():252] probe done
2021-10-13 15:48:14,287 WARNING MainThread:24686 [internal.py:wandb_internal():147] Internal process interrupt: 1
2021-10-13 15:48:14,482 WARNING MainThread:24686 [internal.py:wandb_internal():147] Internal process interrupt: 2
2021-10-13 15:48:14,482 ERROR   MainThread:24686 [internal.py:wandb_internal():150] Internal process interrupted.
2021-10-13 15:48:14,989 INFO    WriterThread:24686 [datastore.py:close():288] close: output/wandb/offline-run-20211013_153637-19kw7vmp/run-19kw7vmp.wandb
2021-10-13 15:48:15,012 INFO    HandlerThread:24686 [handler.py:finish():658] shutting down handler
2021-10-13 15:48:15,467 INFO    SenderThread:24686 [sender.py:finish():947] shutting down sender
2021-10-13 15:48:15,468 INFO    MainThread:24686 [internal.py:handle_exit():78] Internal process exited
