2021-10-07 15:31:43,212 INFO    MainThread:3486 [internal.py:wandb_internal():89] W&B internal server running at pid: 3486, started at: 2021-10-07 15:31:43.212098
2021-10-07 15:31:43,216 INFO    WriterThread:3486 [datastore.py:open_for_write():77] open: output/wandb/offline-run-20211007_153142-1loep9mp/run-1loep9mp.wandb
2021-10-07 15:31:43,216 DEBUG   HandlerThread:3486 [handler.py:handle_request():126] handle_request: run_start
2021-10-07 15:31:46,369 DEBUG   HandlerThread:3486 [meta.py:__init__():40] meta init
2021-10-07 15:31:46,369 DEBUG   HandlerThread:3486 [meta.py:__init__():54] meta init done
2021-10-07 15:31:46,369 DEBUG   HandlerThread:3486 [meta.py:probe():211] probe
2021-10-07 15:31:46,386 DEBUG   HandlerThread:3486 [meta.py:_setup_git():201] setup git
2021-10-07 15:31:46,426 DEBUG   HandlerThread:3486 [meta.py:_setup_git():208] setup git done
2021-10-07 15:31:46,427 DEBUG   HandlerThread:3486 [meta.py:_save_pip():58] save pip
2021-10-07 15:31:46,428 DEBUG   HandlerThread:3486 [meta.py:_save_pip():72] save pip done
2021-10-07 15:31:46,430 DEBUG   HandlerThread:3486 [meta.py:_save_conda():79] save conda
2021-10-07 15:31:53,308 DEBUG   HandlerThread:3486 [meta.py:_save_conda():87] save conda done
2021-10-07 15:31:53,308 DEBUG   HandlerThread:3486 [meta.py:probe():249] probe done
2021-10-07 15:31:53,836 WARNING MainThread:3486 [internal.py:wandb_internal():145] Internal process interrupt: 1
2021-10-07 15:31:54,027 WARNING MainThread:3486 [internal.py:wandb_internal():145] Internal process interrupt: 2
2021-10-07 15:31:54,028 ERROR   MainThread:3486 [internal.py:wandb_internal():148] Internal process interrupted.
2021-10-07 15:31:54,230 INFO    SenderThread:3486 [sender.py:finish():979] shutting down sender
2021-10-07 15:31:54,320 INFO    WriterThread:3486 [datastore.py:close():281] close: output/wandb/offline-run-20211007_153142-1loep9mp/run-1loep9mp.wandb
2021-10-07 15:31:54,321 INFO    HandlerThread:3486 [handler.py:finish():683] shutting down handler
2021-10-07 15:31:54,323 INFO    MainThread:3486 [internal.py:handle_exit():76] Internal process exited
