2021-10-07 15:27:40,849 INFO    MainThread:3186 [internal.py:wandb_internal():89] W&B internal server running at pid: 3186, started at: 2021-10-07 15:27:40.848513
2021-10-07 15:27:40,852 DEBUG   HandlerThread:3186 [handler.py:handle_request():126] handle_request: run_start
2021-10-07 15:27:40,852 INFO    WriterThread:3186 [datastore.py:open_for_write():77] open: output/wandb/offline-run-20211007_152739-24xheoip/run-24xheoip.wandb
2021-10-07 15:27:44,896 DEBUG   HandlerThread:3186 [meta.py:__init__():40] meta init
2021-10-07 15:27:44,897 DEBUG   HandlerThread:3186 [meta.py:__init__():54] meta init done
2021-10-07 15:27:44,897 DEBUG   HandlerThread:3186 [meta.py:probe():211] probe
2021-10-07 15:27:44,916 DEBUG   HandlerThread:3186 [meta.py:_setup_git():201] setup git
2021-10-07 15:27:44,954 DEBUG   HandlerThread:3186 [meta.py:_setup_git():208] setup git done
2021-10-07 15:27:44,954 DEBUG   HandlerThread:3186 [meta.py:_save_pip():58] save pip
2021-10-07 15:27:44,955 DEBUG   HandlerThread:3186 [meta.py:_save_pip():72] save pip done
2021-10-07 15:27:44,955 DEBUG   HandlerThread:3186 [meta.py:_save_conda():79] save conda
2021-10-07 15:27:52,661 DEBUG   HandlerThread:3186 [meta.py:_save_conda():87] save conda done
2021-10-07 15:27:52,661 DEBUG   HandlerThread:3186 [meta.py:probe():249] probe done
2021-10-07 15:27:59,297 WARNING MainThread:3186 [internal.py:wandb_internal():145] Internal process interrupt: 1
2021-10-07 15:27:59,444 WARNING MainThread:3186 [internal.py:wandb_internal():145] Internal process interrupt: 2
2021-10-07 15:27:59,444 ERROR   MainThread:3186 [internal.py:wandb_internal():148] Internal process interrupted.
2021-10-07 15:27:59,670 INFO    WriterThread:3186 [datastore.py:close():281] close: output/wandb/offline-run-20211007_152739-24xheoip/run-24xheoip.wandb
2021-10-07 15:27:59,675 INFO    HandlerThread:3186 [handler.py:finish():683] shutting down handler
2021-10-07 15:27:59,864 INFO    SenderThread:3186 [sender.py:finish():979] shutting down sender
2021-10-07 15:27:59,866 INFO    MainThread:3186 [internal.py:handle_exit():76] Internal process exited
