2021-10-07 14:40:26,399 INFO    MainThread:31923 [internal.py:wandb_internal():89] W&B internal server running at pid: 31923, started at: 2021-10-07 14:40:26.398504
2021-10-07 14:40:26,411 DEBUG   HandlerThread:31923 [handler.py:handle_request():126] handle_request: run_start
2021-10-07 14:40:26,417 INFO    WriterThread:31923 [datastore.py:open_for_write():77] open: output/wandb/offline-run-20211007_144024-1rt0l57u/run-1rt0l57u.wandb
2021-10-07 14:40:30,954 DEBUG   HandlerThread:31923 [meta.py:__init__():40] meta init
2021-10-07 14:40:30,955 DEBUG   HandlerThread:31923 [meta.py:__init__():54] meta init done
2021-10-07 14:40:30,955 DEBUG   HandlerThread:31923 [meta.py:probe():211] probe
2021-10-07 14:40:30,975 DEBUG   HandlerThread:31923 [meta.py:_setup_git():201] setup git
2021-10-07 14:40:31,040 DEBUG   HandlerThread:31923 [meta.py:_setup_git():208] setup git done
2021-10-07 14:40:31,040 DEBUG   HandlerThread:31923 [meta.py:_save_pip():58] save pip
2021-10-07 14:40:31,041 DEBUG   HandlerThread:31923 [meta.py:_save_pip():72] save pip done
2021-10-07 14:40:31,041 DEBUG   HandlerThread:31923 [meta.py:_save_conda():79] save conda
2021-10-07 14:40:37,826 DEBUG   HandlerThread:31923 [meta.py:_save_conda():87] save conda done
2021-10-07 14:40:37,827 DEBUG   HandlerThread:31923 [meta.py:probe():249] probe done
2021-10-07 14:40:55,154 WARNING MainThread:31923 [internal.py:wandb_internal():145] Internal process interrupt: 1
2021-10-07 14:40:55,315 WARNING MainThread:31923 [internal.py:wandb_internal():145] Internal process interrupt: 2
2021-10-07 14:40:55,315 ERROR   MainThread:31923 [internal.py:wandb_internal():148] Internal process interrupted.
2021-10-07 14:40:55,527 INFO    SenderThread:31923 [sender.py:finish():979] shutting down sender
2021-10-07 14:40:55,844 INFO    WriterThread:31923 [datastore.py:close():281] close: output/wandb/offline-run-20211007_144024-1rt0l57u/run-1rt0l57u.wandb
2021-10-07 14:40:55,856 INFO    HandlerThread:31923 [handler.py:finish():683] shutting down handler
2021-10-07 14:40:55,858 INFO    MainThread:31923 [internal.py:handle_exit():76] Internal process exited
