2021-09-23 15:00:47,318 INFO    MainThread:14891 [internal.py:wandb_internal():89] W&B internal server running at pid: 14891, started at: 2021-09-23 15:00:47.316763
2021-09-23 15:00:47,321 INFO    WriterThread:14891 [datastore.py:open_for_write():77] open: output/wandb/offline-run-20210923_150045-1ymjhmbz/run-1ymjhmbz.wandb
2021-09-23 15:00:47,323 DEBUG   HandlerThread:14891 [handler.py:handle_request():126] handle_request: run_start
2021-09-23 15:00:54,011 WARNING MainThread:14891 [internal.py:wandb_internal():145] Internal process interrupt: 1
2021-09-23 15:00:54,160 WARNING MainThread:14891 [internal.py:wandb_internal():145] Internal process interrupt: 2
2021-09-23 15:00:54,160 ERROR   MainThread:14891 [internal.py:wandb_internal():148] Internal process interrupted.
2021-09-23 15:00:54,249 DEBUG   HandlerThread:14891 [meta.py:__init__():40] meta init
2021-09-23 15:00:54,249 DEBUG   HandlerThread:14891 [meta.py:__init__():54] meta init done
2021-09-23 15:00:54,249 DEBUG   HandlerThread:14891 [meta.py:probe():211] probe
2021-09-23 15:00:54,280 DEBUG   HandlerThread:14891 [meta.py:_setup_git():201] setup git
2021-09-23 15:00:54,375 DEBUG   HandlerThread:14891 [meta.py:_setup_git():208] setup git done
2021-09-23 15:00:54,375 DEBUG   HandlerThread:14891 [meta.py:_save_pip():58] save pip
2021-09-23 15:00:54,376 DEBUG   HandlerThread:14891 [meta.py:_save_pip():72] save pip done
2021-09-23 15:00:54,378 DEBUG   HandlerThread:14891 [meta.py:_save_conda():79] save conda
2021-09-23 15:00:54,669 INFO    SenderThread:14891 [sender.py:finish():979] shutting down sender
2021-09-23 15:00:54,670 INFO    WriterThread:14891 [datastore.py:close():281] close: output/wandb/offline-run-20210923_150045-1ymjhmbz/run-1ymjhmbz.wandb
2021-09-23 15:01:02,399 DEBUG   HandlerThread:14891 [meta.py:_save_conda():87] save conda done
2021-09-23 15:01:02,402 DEBUG   HandlerThread:14891 [meta.py:probe():249] probe done
2021-09-23 15:01:02,440 INFO    HandlerThread:14891 [handler.py:finish():683] shutting down handler
2021-09-23 15:01:02,449 INFO    MainThread:14891 [internal.py:handle_exit():76] Internal process exited
