2021-10-13 20:59:24,615 INFO    MainThread:22380 [internal.py:wandb_internal():91] W&B internal server running at pid: 22380, started at: 2021-10-13 20:59:24.614748
2021-10-13 20:59:24,618 INFO    WriterThread:22380 [datastore.py:open_for_write():80] open: output/wandb/offline-run-20211013_205923-9wj6a7b8/run-9wj6a7b8.wandb
2021-10-13 20:59:24,621 DEBUG   HandlerThread:22380 [handler.py:handle_request():124] handle_request: run_start
2021-10-13 20:59:25,598 DEBUG   HandlerThread:22380 [meta.py:__init__():39] meta init
2021-10-13 20:59:25,598 DEBUG   HandlerThread:22380 [meta.py:__init__():53] meta init done
2021-10-13 20:59:25,598 DEBUG   HandlerThread:22380 [meta.py:probe():210] probe
2021-10-13 20:59:25,605 DEBUG   HandlerThread:22380 [meta.py:_setup_git():200] setup git
2021-10-13 20:59:25,630 DEBUG   HandlerThread:22380 [meta.py:_setup_git():207] setup git done
2021-10-13 20:59:25,630 DEBUG   HandlerThread:22380 [meta.py:_save_pip():57] save pip
2021-10-13 20:59:25,631 DEBUG   HandlerThread:22380 [meta.py:_save_pip():71] save pip done
2021-10-13 20:59:25,631 DEBUG   HandlerThread:22380 [meta.py:_save_conda():78] save conda
2021-10-13 20:59:28,406 DEBUG   HandlerThread:22380 [meta.py:_save_conda():86] save conda done
2021-10-13 20:59:28,406 DEBUG   HandlerThread:22380 [meta.py:probe():252] probe done
2021-10-13 20:59:36,118 WARNING MainThread:22380 [internal.py:wandb_internal():147] Internal process interrupt: 1
2021-10-13 20:59:36,287 WARNING MainThread:22380 [internal.py:wandb_internal():147] Internal process interrupt: 2
2021-10-13 20:59:36,287 ERROR   MainThread:22380 [internal.py:wandb_internal():150] Internal process interrupted.
2021-10-13 20:59:36,444 INFO    WriterThread:22380 [datastore.py:close():288] close: output/wandb/offline-run-20211013_205923-9wj6a7b8/run-9wj6a7b8.wandb
2021-10-13 20:59:36,451 INFO    HandlerThread:22380 [handler.py:finish():658] shutting down handler
2021-10-13 20:59:36,627 INFO    SenderThread:22380 [sender.py:finish():947] shutting down sender
2021-10-13 20:59:36,628 INFO    MainThread:22380 [internal.py:handle_exit():78] Internal process exited
