2021-10-07 12:18:01,028 INFO    MainThread:23409 [internal.py:wandb_internal():89] W&B internal server running at pid: 23409, started at: 2021-10-07 12:18:01.027373
2021-10-07 12:18:01,031 INFO    WriterThread:23409 [datastore.py:open_for_write():77] open: output/wandb/offline-run-20211007_121800-25j3a3w5/run-25j3a3w5.wandb
2021-10-07 12:18:01,032 DEBUG   HandlerThread:23409 [handler.py:handle_request():126] handle_request: run_start
2021-10-07 12:18:04,915 DEBUG   HandlerThread:23409 [meta.py:__init__():40] meta init
2021-10-07 12:18:04,915 DEBUG   HandlerThread:23409 [meta.py:__init__():54] meta init done
2021-10-07 12:18:04,915 DEBUG   HandlerThread:23409 [meta.py:probe():211] probe
2021-10-07 12:18:04,933 DEBUG   HandlerThread:23409 [meta.py:_setup_git():201] setup git
2021-10-07 12:18:04,971 DEBUG   HandlerThread:23409 [meta.py:_setup_git():208] setup git done
2021-10-07 12:18:04,972 DEBUG   HandlerThread:23409 [meta.py:_save_pip():58] save pip
2021-10-07 12:18:04,973 DEBUG   HandlerThread:23409 [meta.py:_save_pip():72] save pip done
2021-10-07 12:18:04,973 DEBUG   HandlerThread:23409 [meta.py:_save_conda():79] save conda
2021-10-07 12:18:11,751 DEBUG   HandlerThread:23409 [meta.py:_save_conda():87] save conda done
2021-10-07 12:18:11,752 DEBUG   HandlerThread:23409 [meta.py:probe():249] probe done
2021-10-07 12:18:24,618 WARNING MainThread:23409 [internal.py:wandb_internal():145] Internal process interrupt: 1
2021-10-07 12:18:24,815 WARNING MainThread:23409 [internal.py:wandb_internal():145] Internal process interrupt: 2
2021-10-07 12:18:24,815 ERROR   MainThread:23409 [internal.py:wandb_internal():148] Internal process interrupted.
2021-10-07 12:18:25,041 INFO    SenderThread:23409 [sender.py:finish():979] shutting down sender
2021-10-07 12:18:25,760 INFO    WriterThread:23409 [datastore.py:close():281] close: output/wandb/offline-run-20211007_121800-25j3a3w5/run-25j3a3w5.wandb
2021-10-07 12:18:25,772 INFO    HandlerThread:23409 [handler.py:finish():683] shutting down handler
2021-10-07 12:18:25,773 INFO    MainThread:23409 [internal.py:handle_exit():76] Internal process exited
