2021-10-07 15:36:47,684 INFO    MainThread:3644 [internal.py:wandb_internal():89] W&B internal server running at pid: 3644, started at: 2021-10-07 15:36:47.683320
2021-10-07 15:36:47,687 INFO    WriterThread:3644 [datastore.py:open_for_write():77] open: output/wandb/offline-run-20211007_153646-x1sowna7/run-x1sowna7.wandb
2021-10-07 15:36:47,688 DEBUG   HandlerThread:3644 [handler.py:handle_request():126] handle_request: run_start
2021-10-07 15:36:51,868 DEBUG   HandlerThread:3644 [meta.py:__init__():40] meta init
2021-10-07 15:36:51,868 DEBUG   HandlerThread:3644 [meta.py:__init__():54] meta init done
2021-10-07 15:36:51,868 DEBUG   HandlerThread:3644 [meta.py:probe():211] probe
2021-10-07 15:36:51,892 DEBUG   HandlerThread:3644 [meta.py:_setup_git():201] setup git
2021-10-07 15:36:51,937 DEBUG   HandlerThread:3644 [meta.py:_setup_git():208] setup git done
2021-10-07 15:36:51,938 DEBUG   HandlerThread:3644 [meta.py:_save_pip():58] save pip
2021-10-07 15:36:51,938 DEBUG   HandlerThread:3644 [meta.py:_save_pip():72] save pip done
2021-10-07 15:36:51,939 DEBUG   HandlerThread:3644 [meta.py:_save_conda():79] save conda
2021-10-07 15:36:54,997 WARNING MainThread:3644 [internal.py:wandb_internal():145] Internal process interrupt: 1
2021-10-07 15:36:55,115 DEBUG   HandlerThread:3644 [meta.py:_save_conda():87] save conda done
2021-10-07 15:36:55,116 DEBUG   HandlerThread:3644 [meta.py:probe():249] probe done
2021-10-07 15:36:55,162 WARNING MainThread:3644 [internal.py:wandb_internal():145] Internal process interrupt: 2
2021-10-07 15:36:55,162 ERROR   MainThread:3644 [internal.py:wandb_internal():148] Internal process interrupted.
2021-10-07 15:36:55,806 INFO    SenderThread:3644 [sender.py:finish():979] shutting down sender
2021-10-07 15:36:56,127 INFO    WriterThread:3644 [datastore.py:close():281] close: output/wandb/offline-run-20211007_153646-x1sowna7/run-x1sowna7.wandb
2021-10-07 15:36:56,128 INFO    HandlerThread:3644 [handler.py:finish():683] shutting down handler
2021-10-07 15:36:56,130 INFO    MainThread:3644 [internal.py:handle_exit():76] Internal process exited
