2021-10-13 18:22:50,955 INFO    MainThread:6033 [internal.py:wandb_internal():91] W&B internal server running at pid: 6033, started at: 2021-10-13 18:22:50.954770
2021-10-13 18:22:50,958 INFO    WriterThread:6033 [datastore.py:open_for_write():80] open: output/wandb/offline-run-20211013_182250-2f3r8h70/run-2f3r8h70.wandb
2021-10-13 18:22:50,962 DEBUG   HandlerThread:6033 [handler.py:handle_request():124] handle_request: run_start
2021-10-13 18:22:51,829 DEBUG   HandlerThread:6033 [meta.py:__init__():39] meta init
2021-10-13 18:22:51,829 DEBUG   HandlerThread:6033 [meta.py:__init__():53] meta init done
2021-10-13 18:22:51,829 DEBUG   HandlerThread:6033 [meta.py:probe():210] probe
2021-10-13 18:22:51,836 DEBUG   HandlerThread:6033 [meta.py:_setup_git():200] setup git
2021-10-13 18:22:51,857 DEBUG   HandlerThread:6033 [meta.py:_setup_git():207] setup git done
2021-10-13 18:22:51,858 DEBUG   HandlerThread:6033 [meta.py:_save_pip():57] save pip
2021-10-13 18:22:51,859 DEBUG   HandlerThread:6033 [meta.py:_save_pip():71] save pip done
2021-10-13 18:22:51,859 DEBUG   HandlerThread:6033 [meta.py:_save_conda():78] save conda
2021-10-13 18:22:54,639 DEBUG   HandlerThread:6033 [meta.py:_save_conda():86] save conda done
2021-10-13 18:22:54,639 DEBUG   HandlerThread:6033 [meta.py:probe():252] probe done
2021-10-13 18:23:02,956 WARNING MainThread:6033 [internal.py:wandb_internal():147] Internal process interrupt: 1
2021-10-13 18:23:03,135 WARNING MainThread:6033 [internal.py:wandb_internal():147] Internal process interrupt: 2
2021-10-13 18:23:03,136 ERROR   MainThread:6033 [internal.py:wandb_internal():150] Internal process interrupted.
2021-10-13 18:23:03,677 INFO    WriterThread:6033 [datastore.py:close():288] close: output/wandb/offline-run-20211013_182250-2f3r8h70/run-2f3r8h70.wandb
2021-10-13 18:23:03,684 INFO    HandlerThread:6033 [handler.py:finish():658] shutting down handler
2021-10-13 18:23:03,964 INFO    SenderThread:6033 [sender.py:finish():947] shutting down sender
2021-10-13 18:23:03,965 INFO    MainThread:6033 [internal.py:handle_exit():78] Internal process exited
