2021-10-07 16:51:30,463 INFO    MainThread:8150 [internal.py:wandb_internal():89] W&B internal server running at pid: 8150, started at: 2021-10-07 16:51:30.462828
2021-10-07 16:51:30,471 INFO    WriterThread:8150 [datastore.py:open_for_write():77] open: output/wandb/offline-run-20211007_165129-2z859qrc/run-2z859qrc.wandb
2021-10-07 16:51:30,473 DEBUG   HandlerThread:8150 [handler.py:handle_request():126] handle_request: run_start
2021-10-07 16:51:32,276 DEBUG   HandlerThread:8150 [meta.py:__init__():40] meta init
2021-10-07 16:51:32,277 DEBUG   HandlerThread:8150 [meta.py:__init__():54] meta init done
2021-10-07 16:51:32,277 DEBUG   HandlerThread:8150 [meta.py:probe():211] probe
2021-10-07 16:51:32,292 DEBUG   HandlerThread:8150 [meta.py:_setup_git():201] setup git
2021-10-07 16:51:32,323 DEBUG   HandlerThread:8150 [meta.py:_setup_git():208] setup git done
2021-10-07 16:51:32,324 DEBUG   HandlerThread:8150 [meta.py:_save_pip():58] save pip
2021-10-07 16:51:32,324 DEBUG   HandlerThread:8150 [meta.py:_save_pip():72] save pip done
2021-10-07 16:51:32,324 DEBUG   HandlerThread:8150 [meta.py:_save_conda():79] save conda
2021-10-07 16:51:37,639 DEBUG   HandlerThread:8150 [meta.py:_save_conda():87] save conda done
2021-10-07 16:51:37,639 DEBUG   HandlerThread:8150 [meta.py:probe():249] probe done
2021-10-07 16:51:39,634 WARNING MainThread:8150 [internal.py:wandb_internal():145] Internal process interrupt: 1
2021-10-07 16:51:39,801 WARNING MainThread:8150 [internal.py:wandb_internal():145] Internal process interrupt: 2
2021-10-07 16:51:39,802 ERROR   MainThread:8150 [internal.py:wandb_internal():148] Internal process interrupted.
2021-10-07 16:51:40,478 INFO    SenderThread:8150 [sender.py:finish():979] shutting down sender
2021-10-07 16:51:40,644 INFO    WriterThread:8150 [datastore.py:close():281] close: output/wandb/offline-run-20211007_165129-2z859qrc/run-2z859qrc.wandb
2021-10-07 16:51:40,647 INFO    HandlerThread:8150 [handler.py:finish():683] shutting down handler
2021-10-07 16:51:40,649 INFO    MainThread:8150 [internal.py:handle_exit():76] Internal process exited
