2021-10-07 14:24:05,251 INFO    MainThread:30916 [internal.py:wandb_internal():89] W&B internal server running at pid: 30916, started at: 2021-10-07 14:24:05.250526
2021-10-07 14:24:05,255 DEBUG   HandlerThread:30916 [handler.py:handle_request():126] handle_request: run_start
2021-10-07 14:24:05,258 INFO    WriterThread:30916 [datastore.py:open_for_write():77] open: output/wandb/offline-run-20211007_142404-3ujbme94/run-3ujbme94.wandb
2021-10-07 14:24:08,218 DEBUG   HandlerThread:30916 [meta.py:__init__():40] meta init
2021-10-07 14:24:08,218 DEBUG   HandlerThread:30916 [meta.py:__init__():54] meta init done
2021-10-07 14:24:08,218 DEBUG   HandlerThread:30916 [meta.py:probe():211] probe
2021-10-07 14:24:08,237 DEBUG   HandlerThread:30916 [meta.py:_setup_git():201] setup git
2021-10-07 14:24:08,268 DEBUG   HandlerThread:30916 [meta.py:_setup_git():208] setup git done
2021-10-07 14:24:08,268 DEBUG   HandlerThread:30916 [meta.py:_save_pip():58] save pip
2021-10-07 14:24:08,268 DEBUG   HandlerThread:30916 [meta.py:_save_pip():72] save pip done
2021-10-07 14:24:08,269 DEBUG   HandlerThread:30916 [meta.py:_save_conda():79] save conda
2021-10-07 14:24:14,773 DEBUG   HandlerThread:30916 [meta.py:_save_conda():87] save conda done
2021-10-07 14:24:14,773 DEBUG   HandlerThread:30916 [meta.py:probe():249] probe done
2021-10-07 14:24:16,874 WARNING MainThread:30916 [internal.py:wandb_internal():145] Internal process interrupt: 1
2021-10-07 14:24:17,273 WARNING MainThread:30916 [internal.py:wandb_internal():145] Internal process interrupt: 2
2021-10-07 14:24:17,274 ERROR   MainThread:30916 [internal.py:wandb_internal():148] Internal process interrupted.
2021-10-07 14:24:17,785 INFO    WriterThread:30916 [datastore.py:close():281] close: output/wandb/offline-run-20211007_142404-3ujbme94/run-3ujbme94.wandb
2021-10-07 14:24:17,787 INFO    HandlerThread:30916 [handler.py:finish():683] shutting down handler
2021-10-07 14:24:18,262 INFO    SenderThread:30916 [sender.py:finish():979] shutting down sender
2021-10-07 14:24:18,264 INFO    MainThread:30916 [internal.py:handle_exit():76] Internal process exited
