2021-10-12 16:20:16,202 INFO    MainThread:27712 [internal.py:wandb_internal():91] W&B internal server running at pid: 27712, started at: 2021-10-12 16:20:16.201789
2021-10-12 16:20:16,205 INFO    WriterThread:27712 [datastore.py:open_for_write():80] open: output/wandb/offline-run-20211012_162015-3bqb4wsu/run-3bqb4wsu.wandb
2021-10-12 16:20:16,208 DEBUG   HandlerThread:27712 [handler.py:handle_request():124] handle_request: run_start
2021-10-12 16:20:17,088 DEBUG   HandlerThread:27712 [meta.py:__init__():39] meta init
2021-10-12 16:20:17,088 DEBUG   HandlerThread:27712 [meta.py:__init__():53] meta init done
2021-10-12 16:20:17,088 DEBUG   HandlerThread:27712 [meta.py:probe():210] probe
2021-10-12 16:20:17,094 DEBUG   HandlerThread:27712 [meta.py:_setup_git():200] setup git
2021-10-12 16:20:17,117 DEBUG   HandlerThread:27712 [meta.py:_setup_git():207] setup git done
2021-10-12 16:20:17,117 DEBUG   HandlerThread:27712 [meta.py:_save_pip():57] save pip
2021-10-12 16:20:17,118 DEBUG   HandlerThread:27712 [meta.py:_save_pip():71] save pip done
2021-10-12 16:20:17,118 DEBUG   HandlerThread:27712 [meta.py:_save_conda():78] save conda
2021-10-12 16:20:19,958 DEBUG   HandlerThread:27712 [meta.py:_save_conda():86] save conda done
2021-10-12 16:20:19,958 DEBUG   HandlerThread:27712 [meta.py:probe():252] probe done
2021-10-12 16:37:55,504 WARNING MainThread:27712 [internal.py:wandb_internal():147] Internal process interrupt: 1
2021-10-12 16:37:55,645 WARNING MainThread:27712 [internal.py:wandb_internal():147] Internal process interrupt: 2
2021-10-12 16:37:55,645 ERROR   MainThread:27712 [internal.py:wandb_internal():150] Internal process interrupted.
2021-10-12 16:37:56,340 INFO    WriterThread:27712 [datastore.py:close():288] close: output/wandb/offline-run-20211012_162015-3bqb4wsu/run-3bqb4wsu.wandb
2021-10-12 16:37:56,365 INFO    HandlerThread:27712 [handler.py:finish():658] shutting down handler
2021-10-12 16:37:56,376 INFO    SenderThread:27712 [sender.py:finish():947] shutting down sender
2021-10-12 16:37:56,377 INFO    MainThread:27712 [internal.py:handle_exit():78] Internal process exited
