2021-10-07 11:55:32,310 INFO    MainThread:22269 [internal.py:wandb_internal():89] W&B internal server running at pid: 22269, started at: 2021-10-07 11:55:32.310062
2021-10-07 11:55:32,313 INFO    WriterThread:22269 [datastore.py:open_for_write():77] open: output/wandb/offline-run-20211007_115531-mfdwsa6b/run-mfdwsa6b.wandb
2021-10-07 11:55:32,315 DEBUG   HandlerThread:22269 [handler.py:handle_request():126] handle_request: run_start
2021-10-07 11:55:36,934 DEBUG   HandlerThread:22269 [meta.py:__init__():40] meta init
2021-10-07 11:55:36,936 DEBUG   HandlerThread:22269 [meta.py:__init__():54] meta init done
2021-10-07 11:55:36,937 DEBUG   HandlerThread:22269 [meta.py:probe():211] probe
2021-10-07 11:55:36,951 DEBUG   HandlerThread:22269 [meta.py:_setup_git():201] setup git
2021-10-07 11:55:37,031 DEBUG   HandlerThread:22269 [meta.py:_setup_git():208] setup git done
2021-10-07 11:55:37,033 DEBUG   HandlerThread:22269 [meta.py:_save_pip():58] save pip
2021-10-07 11:55:37,038 DEBUG   HandlerThread:22269 [meta.py:_save_pip():72] save pip done
2021-10-07 11:55:37,040 DEBUG   HandlerThread:22269 [meta.py:_save_conda():79] save conda
2021-10-07 11:55:45,481 DEBUG   HandlerThread:22269 [meta.py:_save_conda():87] save conda done
2021-10-07 11:55:45,481 DEBUG   HandlerThread:22269 [meta.py:probe():249] probe done
2021-10-07 11:55:58,663 WARNING MainThread:22269 [internal.py:wandb_internal():145] Internal process interrupt: 1
2021-10-07 11:55:58,849 WARNING MainThread:22269 [internal.py:wandb_internal():145] Internal process interrupt: 2
2021-10-07 11:55:58,849 ERROR   MainThread:22269 [internal.py:wandb_internal():148] Internal process interrupted.
2021-10-07 11:55:59,329 INFO    SenderThread:22269 [sender.py:finish():979] shutting down sender
2021-10-07 11:55:59,495 INFO    WriterThread:22269 [datastore.py:close():281] close: output/wandb/offline-run-20211007_115531-mfdwsa6b/run-mfdwsa6b.wandb
2021-10-07 11:55:59,505 INFO    HandlerThread:22269 [handler.py:finish():683] shutting down handler
2021-10-07 11:55:59,508 INFO    MainThread:22269 [internal.py:handle_exit():76] Internal process exited
