2021-09-28 15:35:24,364 INFO    MainThread:21461 [internal.py:wandb_internal():89] W&B internal server running at pid: 21461, started at: 2021-09-28 15:35:24.363783
2021-09-28 15:35:24,368 DEBUG   HandlerThread:21461 [handler.py:handle_request():126] handle_request: run_start
2021-09-28 15:35:24,368 INFO    WriterThread:21461 [datastore.py:open_for_write():77] open: output/wandb/offline-run-20210928_153523-2f1n2k2l/run-2f1n2k2l.wandb
2021-09-28 15:35:26,121 DEBUG   HandlerThread:21461 [meta.py:__init__():40] meta init
2021-09-28 15:35:26,121 DEBUG   HandlerThread:21461 [meta.py:__init__():54] meta init done
2021-09-28 15:35:26,121 DEBUG   HandlerThread:21461 [meta.py:probe():211] probe
2021-09-28 15:35:26,136 DEBUG   HandlerThread:21461 [meta.py:_setup_git():201] setup git
2021-09-28 15:35:26,168 DEBUG   HandlerThread:21461 [meta.py:_setup_git():208] setup git done
2021-09-28 15:35:26,169 DEBUG   HandlerThread:21461 [meta.py:_save_pip():58] save pip
2021-09-28 15:35:26,170 DEBUG   HandlerThread:21461 [meta.py:_save_pip():72] save pip done
2021-09-28 15:35:26,170 DEBUG   HandlerThread:21461 [meta.py:_save_conda():79] save conda
2021-09-28 15:35:30,973 DEBUG   HandlerThread:21461 [meta.py:_save_conda():87] save conda done
2021-09-28 15:35:30,973 DEBUG   HandlerThread:21461 [meta.py:probe():249] probe done
2021-09-28 15:35:33,953 WARNING MainThread:21461 [internal.py:wandb_internal():145] Internal process interrupt: 1
2021-09-28 15:35:34,110 WARNING MainThread:21461 [internal.py:wandb_internal():145] Internal process interrupt: 2
2021-09-28 15:35:34,110 ERROR   MainThread:21461 [internal.py:wandb_internal():148] Internal process interrupted.
2021-09-28 15:35:34,372 INFO    SenderThread:21461 [sender.py:finish():979] shutting down sender
2021-09-28 15:35:34,978 INFO    WriterThread:21461 [datastore.py:close():281] close: output/wandb/offline-run-20210928_153523-2f1n2k2l/run-2f1n2k2l.wandb
2021-09-28 15:35:34,982 INFO    HandlerThread:21461 [handler.py:finish():683] shutting down handler
2021-09-28 15:35:34,983 INFO    MainThread:21461 [internal.py:handle_exit():76] Internal process exited
