2021-09-23 15:42:41,694 INFO    MainThread:17841 [internal.py:wandb_internal():89] W&B internal server running at pid: 17841, started at: 2021-09-23 15:42:41.684395
2021-09-23 15:42:41,702 DEBUG   HandlerThread:17841 [handler.py:handle_request():126] handle_request: run_start
2021-09-23 15:42:41,715 INFO    WriterThread:17841 [datastore.py:open_for_write():77] open: output/wandb/offline-run-20210923_154240-14a03500/run-14a03500.wandb
2021-09-23 15:42:48,302 DEBUG   HandlerThread:17841 [meta.py:__init__():40] meta init
2021-09-23 15:42:48,303 DEBUG   HandlerThread:17841 [meta.py:__init__():54] meta init done
2021-09-23 15:42:48,303 DEBUG   HandlerThread:17841 [meta.py:probe():211] probe
2021-09-23 15:42:48,334 DEBUG   HandlerThread:17841 [meta.py:_setup_git():201] setup git
2021-09-23 15:42:48,397 DEBUG   HandlerThread:17841 [meta.py:_setup_git():208] setup git done
2021-09-23 15:42:48,398 DEBUG   HandlerThread:17841 [meta.py:_save_pip():58] save pip
2021-09-23 15:42:48,404 DEBUG   HandlerThread:17841 [meta.py:_save_pip():72] save pip done
2021-09-23 15:42:48,408 DEBUG   HandlerThread:17841 [meta.py:_save_conda():79] save conda
2021-09-23 15:42:56,767 DEBUG   HandlerThread:17841 [meta.py:_save_conda():87] save conda done
2021-09-23 15:42:56,767 DEBUG   HandlerThread:17841 [meta.py:probe():249] probe done
2021-09-23 15:43:39,679 WARNING MainThread:17841 [internal.py:wandb_internal():145] Internal process interrupt: 1
2021-09-23 15:43:39,848 WARNING MainThread:17841 [internal.py:wandb_internal():145] Internal process interrupt: 2
2021-09-23 15:43:39,849 ERROR   MainThread:17841 [internal.py:wandb_internal():148] Internal process interrupted.
2021-09-23 15:43:40,124 INFO    SenderThread:17841 [sender.py:finish():979] shutting down sender
2021-09-23 15:43:40,450 INFO    WriterThread:17841 [datastore.py:close():281] close: output/wandb/offline-run-20210923_154240-14a03500/run-14a03500.wandb
2021-09-23 15:43:40,473 INFO    HandlerThread:17841 [handler.py:finish():683] shutting down handler
2021-09-23 15:43:40,474 INFO    MainThread:17841 [internal.py:handle_exit():76] Internal process exited
