2021-08-30 17:15:27,532 INFO    MainThread:35668 [internal.py:wandb_internal():91] W&B internal server running at pid: 35668, started at: 2021-08-30 17:15:27.532537
2021-08-30 17:15:27,533 DEBUG   HandlerThread:35668 [handler.py:handle_request():124] handle_request: run_start
2021-08-30 17:15:27,534 INFO    WriterThread:35668 [datastore.py:open_for_write():80] open: output/wandb/offline-run-20210830_171527-tg3wro1l/run-tg3wro1l.wandb
2021-08-30 17:15:27,537 DEBUG   HandlerThread:35668 [meta.py:__init__():34] meta init
2021-08-30 17:15:27,538 DEBUG   HandlerThread:35668 [meta.py:__init__():48] meta init done
2021-08-30 17:15:27,538 DEBUG   HandlerThread:35668 [meta.py:probe():205] probe
2021-08-30 17:15:27,544 DEBUG   HandlerThread:35668 [meta.py:_setup_git():195] setup git
2021-08-30 17:15:27,551 DEBUG   HandlerThread:35668 [meta.py:_setup_git():202] setup git done
2021-08-30 17:15:27,551 DEBUG   HandlerThread:35668 [meta.py:_save_pip():52] save pip
2021-08-30 17:15:27,551 DEBUG   HandlerThread:35668 [meta.py:_save_pip():66] save pip done
2021-08-30 17:15:27,551 DEBUG   HandlerThread:35668 [meta.py:_save_conda():73] save conda
2021-08-30 17:15:29,100 DEBUG   HandlerThread:35668 [meta.py:_save_conda():81] save conda done
2021-08-30 17:15:29,100 DEBUG   HandlerThread:35668 [meta.py:probe():247] probe done
2021-08-30 17:16:40,878 WARNING MainThread:35668 [internal.py:wandb_internal():147] Internal process interrupt: 1
2021-08-30 17:16:41,145 WARNING MainThread:35668 [internal.py:wandb_internal():147] Internal process interrupt: 2
2021-08-30 17:16:41,145 ERROR   MainThread:35668 [internal.py:wandb_internal():150] Internal process interrupted.
2021-08-30 17:16:41,552 INFO    SenderThread:35668 [sender.py:finish():947] shutting down sender
2021-08-30 17:16:41,881 INFO    WriterThread:35668 [datastore.py:close():288] close: output/wandb/offline-run-20210830_171527-tg3wro1l/run-tg3wro1l.wandb
2021-08-30 17:16:41,881 INFO    HandlerThread:35668 [handler.py:finish():658] shutting down handler
2021-08-30 17:16:41,882 INFO    MainThread:35668 [internal.py:handle_exit():78] Internal process exited
