2021-10-11 17:42:35,326 INFO    MainThread:25092 [internal.py:wandb_internal():91] W&B internal server running at pid: 25092, started at: 2021-10-11 17:42:35.326591
2021-10-11 17:42:35,330 INFO    WriterThread:25092 [datastore.py:open_for_write():80] open: output/wandb/offline-run-20211011_174234-vq61tkvk/run-vq61tkvk.wandb
2021-10-11 17:42:35,332 DEBUG   HandlerThread:25092 [handler.py:handle_request():124] handle_request: run_start
2021-10-11 17:42:36,210 DEBUG   HandlerThread:25092 [meta.py:__init__():39] meta init
2021-10-11 17:42:36,210 DEBUG   HandlerThread:25092 [meta.py:__init__():53] meta init done
2021-10-11 17:42:36,210 DEBUG   HandlerThread:25092 [meta.py:probe():210] probe
2021-10-11 17:42:36,217 DEBUG   HandlerThread:25092 [meta.py:_setup_git():200] setup git
2021-10-11 17:42:36,240 DEBUG   HandlerThread:25092 [meta.py:_setup_git():207] setup git done
2021-10-11 17:42:36,240 DEBUG   HandlerThread:25092 [meta.py:_save_pip():57] save pip
2021-10-11 17:42:36,241 DEBUG   HandlerThread:25092 [meta.py:_save_pip():71] save pip done
2021-10-11 17:42:36,241 DEBUG   HandlerThread:25092 [meta.py:_save_conda():78] save conda
2021-10-11 17:42:39,061 DEBUG   HandlerThread:25092 [meta.py:_save_conda():86] save conda done
2021-10-11 17:42:39,061 DEBUG   HandlerThread:25092 [meta.py:probe():252] probe done
2021-10-11 17:43:04,954 WARNING MainThread:25092 [internal.py:wandb_internal():147] Internal process interrupt: 1
2021-10-11 17:43:05,135 WARNING MainThread:25092 [internal.py:wandb_internal():147] Internal process interrupt: 2
2021-10-11 17:43:05,135 ERROR   MainThread:25092 [internal.py:wandb_internal():150] Internal process interrupted.
2021-10-11 17:43:05,339 INFO    SenderThread:25092 [sender.py:finish():947] shutting down sender
2021-10-11 17:43:05,650 INFO    WriterThread:25092 [datastore.py:close():288] close: output/wandb/offline-run-20211011_174234-vq61tkvk/run-vq61tkvk.wandb
2021-10-11 17:43:05,650 INFO    HandlerThread:25092 [handler.py:finish():658] shutting down handler
2021-10-11 17:43:05,651 INFO    MainThread:25092 [internal.py:handle_exit():78] Internal process exited
