2021-10-11 15:58:33,748 INFO    MainThread:16121 [internal.py:wandb_internal():91] W&B internal server running at pid: 16121, started at: 2021-10-11 15:58:33.748072
2021-10-11 15:58:33,751 INFO    WriterThread:16121 [datastore.py:open_for_write():80] open: output/wandb/offline-run-20211011_155832-2ocd5tis/run-2ocd5tis.wandb
2021-10-11 15:58:33,754 DEBUG   HandlerThread:16121 [handler.py:handle_request():124] handle_request: run_start
2021-10-11 15:58:34,629 DEBUG   HandlerThread:16121 [meta.py:__init__():39] meta init
2021-10-11 15:58:34,629 DEBUG   HandlerThread:16121 [meta.py:__init__():53] meta init done
2021-10-11 15:58:34,629 DEBUG   HandlerThread:16121 [meta.py:probe():210] probe
2021-10-11 15:58:34,636 DEBUG   HandlerThread:16121 [meta.py:_setup_git():200] setup git
2021-10-11 15:58:34,659 DEBUG   HandlerThread:16121 [meta.py:_setup_git():207] setup git done
2021-10-11 15:58:34,660 DEBUG   HandlerThread:16121 [meta.py:_save_pip():57] save pip
2021-10-11 15:58:34,661 DEBUG   HandlerThread:16121 [meta.py:_save_pip():71] save pip done
2021-10-11 15:58:34,661 DEBUG   HandlerThread:16121 [meta.py:_save_conda():78] save conda
2021-10-11 15:58:37,494 DEBUG   HandlerThread:16121 [meta.py:_save_conda():86] save conda done
2021-10-11 15:58:37,494 DEBUG   HandlerThread:16121 [meta.py:probe():252] probe done
2021-10-11 16:01:47,424 WARNING MainThread:16121 [internal.py:wandb_internal():147] Internal process interrupt: 1
2021-10-11 16:01:47,593 WARNING MainThread:16121 [internal.py:wandb_internal():147] Internal process interrupt: 2
2021-10-11 16:01:47,594 ERROR   MainThread:16121 [internal.py:wandb_internal():150] Internal process interrupted.
2021-10-11 16:01:47,787 INFO    SenderThread:16121 [sender.py:finish():947] shutting down sender
2021-10-11 16:01:48,043 INFO    WriterThread:16121 [datastore.py:close():288] close: output/wandb/offline-run-20211011_155832-2ocd5tis/run-2ocd5tis.wandb
2021-10-11 16:01:48,054 INFO    HandlerThread:16121 [handler.py:finish():658] shutting down handler
2021-10-11 16:01:48,055 INFO    MainThread:16121 [internal.py:handle_exit():78] Internal process exited
