2021-10-13 19:53:12,104 INFO    MainThread:10247 [internal.py:wandb_internal():91] W&B internal server running at pid: 10247, started at: 2021-10-13 19:53:12.104024
2021-10-13 19:53:12,107 INFO    WriterThread:10247 [datastore.py:open_for_write():80] open: output/wandb/offline-run-20211013_195311-dce3x5cg/run-dce3x5cg.wandb
2021-10-13 19:53:12,109 DEBUG   HandlerThread:10247 [handler.py:handle_request():124] handle_request: run_start
2021-10-13 19:53:13,048 DEBUG   HandlerThread:10247 [meta.py:__init__():39] meta init
2021-10-13 19:53:13,048 DEBUG   HandlerThread:10247 [meta.py:__init__():53] meta init done
2021-10-13 19:53:13,048 DEBUG   HandlerThread:10247 [meta.py:probe():210] probe
2021-10-13 19:53:13,055 DEBUG   HandlerThread:10247 [meta.py:_setup_git():200] setup git
2021-10-13 19:53:13,081 DEBUG   HandlerThread:10247 [meta.py:_setup_git():207] setup git done
2021-10-13 19:53:13,082 DEBUG   HandlerThread:10247 [meta.py:_save_pip():57] save pip
2021-10-13 19:53:13,082 DEBUG   HandlerThread:10247 [meta.py:_save_pip():71] save pip done
2021-10-13 19:53:13,082 DEBUG   HandlerThread:10247 [meta.py:_save_conda():78] save conda
2021-10-13 19:53:16,033 DEBUG   HandlerThread:10247 [meta.py:_save_conda():86] save conda done
2021-10-13 19:53:16,033 DEBUG   HandlerThread:10247 [meta.py:probe():252] probe done
2021-10-13 19:53:25,018 WARNING MainThread:10247 [internal.py:wandb_internal():147] Internal process interrupt: 1
2021-10-13 19:53:25,203 WARNING MainThread:10247 [internal.py:wandb_internal():147] Internal process interrupt: 2
2021-10-13 19:53:25,203 ERROR   MainThread:10247 [internal.py:wandb_internal():150] Internal process interrupted.
2021-10-13 19:53:26,072 INFO    WriterThread:10247 [datastore.py:close():288] close: output/wandb/offline-run-20211013_195311-dce3x5cg/run-dce3x5cg.wandb
2021-10-13 19:53:26,080 INFO    HandlerThread:10247 [handler.py:finish():658] shutting down handler
2021-10-13 19:53:26,115 INFO    SenderThread:10247 [sender.py:finish():947] shutting down sender
2021-10-13 19:53:26,116 INFO    MainThread:10247 [internal.py:handle_exit():78] Internal process exited
