2021-10-06 18:27:57,177 INFO    MainThread:14092 [internal.py:wandb_internal():91] W&B internal server running at pid: 14092, started at: 2021-10-06 18:27:57.176963
2021-10-06 18:27:57,180 DEBUG   HandlerThread:14092 [handler.py:handle_request():124] handle_request: run_start
2021-10-06 18:27:57,180 INFO    WriterThread:14092 [datastore.py:open_for_write():80] open: output/wandb/offline-run-20211006_182756-yzgw3o6t/run-yzgw3o6t.wandb
2021-10-06 18:27:58,059 DEBUG   HandlerThread:14092 [meta.py:__init__():39] meta init
2021-10-06 18:27:58,059 DEBUG   HandlerThread:14092 [meta.py:__init__():53] meta init done
2021-10-06 18:27:58,059 DEBUG   HandlerThread:14092 [meta.py:probe():210] probe
2021-10-06 18:27:58,065 DEBUG   HandlerThread:14092 [meta.py:_setup_git():200] setup git
2021-10-06 18:27:58,089 DEBUG   HandlerThread:14092 [meta.py:_setup_git():207] setup git done
2021-10-06 18:27:58,089 DEBUG   HandlerThread:14092 [meta.py:_save_pip():57] save pip
2021-10-06 18:27:58,090 DEBUG   HandlerThread:14092 [meta.py:_save_pip():71] save pip done
2021-10-06 18:27:58,090 DEBUG   HandlerThread:14092 [meta.py:_save_conda():78] save conda
2021-10-06 18:28:01,523 DEBUG   HandlerThread:14092 [meta.py:_save_conda():86] save conda done
2021-10-06 18:28:01,523 DEBUG   HandlerThread:14092 [meta.py:probe():252] probe done
2021-10-06 18:51:20,496 WARNING MainThread:14092 [internal.py:wandb_internal():147] Internal process interrupt: 1
2021-10-06 18:51:20,670 WARNING MainThread:14092 [internal.py:wandb_internal():147] Internal process interrupt: 2
2021-10-06 18:51:20,670 ERROR   MainThread:14092 [internal.py:wandb_internal():150] Internal process interrupted.
2021-10-06 18:51:21,115 INFO    WriterThread:14092 [datastore.py:close():288] close: output/wandb/offline-run-20211006_182756-yzgw3o6t/run-yzgw3o6t.wandb
2021-10-06 18:51:21,122 INFO    HandlerThread:14092 [handler.py:finish():658] shutting down handler
2021-10-06 18:51:21,404 INFO    SenderThread:14092 [sender.py:finish():947] shutting down sender
2021-10-06 18:51:21,406 INFO    MainThread:14092 [internal.py:handle_exit():78] Internal process exited
